Workbook

Sheet Ficha Distr EPI
B2: DISTRIBUIÇÃO DE EPI - ARMAZÉM | G2: Nr
B4: QTD | C4: Artigo | D4: Descrição / Ref.ª EPI | E4: Risco Associado | F4: Tamanho | G4: Nº Série
A6: =D6 -> CALÇA IMPERMIÁVEL TAM. L | B6: 1 | C6: 3000377 | D6: CALÇA IMPERMIÁVEL TAM. L
A7: =D7 -> PARKA IMPERM. ALTA VISIB. TAM. XXL | B7: 1 | C7: 3001021 | D7: PARKA IMPERM. ALTA VISIB. TAM. XXL | E7: =IFERROR(VLOOKUP(C7,Primavera!A:D,4,FALSE),"") -> 5; 11; 13
A8: =D8 -> T-SHIRT TAM. XXL | B8: 5 | C8: 3001376 | D8: T-SHIRT TAM. XXL | E8: =IFERROR(VLOOKUP(C8,Primavera!A:D,4,FALSE),"") -> 5; 11; 13
A9: =D9 -> CAMISOLA MANGA COMPRIDA TAM. XXL | B9: 3 | C9: 3000390 | D9: CAMISOLA MANGA COMPRIDA TAM. XXL | E9: =IFERROR(VLOOKUP(C9,Primavera!A:D,4,FALSE),"") -> 5; 11; 28
A10: =D10 -> LUVAS NITRIL PRETO TAM. L | B10: 1 | C10: 3000838 | D10: LUVAS NITRIL PRETO TAM. L | E10: =IFERROR(VLOOKUP(C10,Primavera!A:D,4,FALSE),"") -> 5; 6; 13; 14
A11: =D11 -> LUVAS LATEX TAM. L | B11: 1 | C11: 3000832 | D11: LUVAS LATEX TAM. L | E11: =IFERROR(VLOOKUP(C11,Primavera!A:D,4,FALSE),"") -> 5; 6; 13; 14
A12: =D12 -> BOTA PVC BIQ/PALM AÇO SAFETY T43 | B12: 1 | C12: 3000254 | D12: BOTA PVC BIQ/PALM AÇO SAFETY T43 | E12: =IFERROR(VLOOKUP(C12,Primavera!A:D,4,FALSE),"") -> 3; 4; 6; 11; 12; 13; 20
A13: =D13 -> CAPACETE C/ FITA DE APERTO | B13: 1 | C13: 3000393 | D13: CAPACETE C/ FITA DE APERTO | E13: =IFERROR(VLOOKUP(C13,Primavera!A:D,4,FALSE),"") -> 1; 2; 3; 9; 12; 13
A14: =D14 -> 0 | C14: =IFERROR(VLOOKUP(A14,Primavera!B:D,2,FALSE),"") | E14: =IFERROR(VLOOKUP(C14,Primavera!A:D,4,FALSE),"")
A15: =D15 -> 0 | C15: =IFERROR(VLOOKUP(A15,Primavera!B:D,2,FALSE),"") | E15: =IFERROR(VLOOKUP(C15,Primavera!A:D,4,FALSE),"")
A16: =D16 -> 0 | C16: =IFERROR(VLOOKUP(A16,Primavera!B:D,2,FALSE),"") | E16: =IFERROR(VLOOKUP(C16,Primavera!A:D,4,FALSE),"")
A17: =D17 -> 0 | C17: =IFERROR(VLOOKUP(A17,Primavera!B:D,2,FALSE),"") | E17: =IFERROR(VLOOKUP(C17,Primavera!A:D,4,FALSE),"")
B19: Declaração (DL 348/93 de 1 de Outubro)
B21: Declaro(a) que recebi os Equipamentos de Proteção Individual (EPI) acima mencionados e que fui informado(a) dos respetivos riscos que pretendem proteger, comprometendo-me a utilizá-los corretamene de acordo com as instruções recebidas, a conservá-los e mantê-los em bom estado, e a participar ao meu superior hierárquico todas as avarias ou deficiências de que tenha conhecimento.
B27: Superior Hierárquico:
D28: Nome: Ricardo Faria | F28: Data: | G28: 46112
B30: Armazém: (quem entregou o EPI)
D32: Assinatura: __________________________________________________________ | F32: Data:
B34: Colaborador(a): | D34: Rafael Lopes Lessa
F35: Nr. Colab. | G35: 2988
D36: Assinatura: _________________________________________________________ | F36: Data:

Sheet Nº Riscos
B2: RISCOS A PROTEGER
B3: Nº | C3: Risco
B4: 1 | C4: Queda em Altura
B5: 2 | C5: Queda ao Mesmo ou com Desnível
B6: 3 | C6: Queda de Objetos
B7: 4 | C7: Esmagamento
B8: 5 | C8: Queimadura
B9: 6 | C9: Entalamento
B10: 7 | C10: Atropelamento
B11: 8 | C11: Eletrocussão/ Eletrização
B12: 9 | C12: Pancada na Cabeça
B13: 10 | C13: Exposição ao Ruído
B14: 11 | C14: Exposição Agentes Químicos/ Poeiras
B15: 12 | C15: Choque com ou contra Objetos/ Equipamentos em movimento ou imóveis
... B17: 14 | C17: Golpe, Corte e /ou Perfuração

Sheet Primavera
A1: Artigo | B1: Descrição | C1: Artigo | D1: Cod Risco
A2: 3000169 | B2: ARNÊS SEGURANÇA P-60 ROZM TAM. M - XL | C2: 3000169 | D2: 1
A3: 3000170 | B3: ARNÊS SEGURANÇA P-71 TAM. M - XL | C3: 3000170 | D3: 1
A4: 3000171 | B4: ARNÊS SEGURANÇA P-90 TAM. M - XL | C4: 3000171 | D4: 1
A5: 3000216 | B5: BOTA BORBA T37 | C5: 3000216 | D5: 3; 4; 6; 11; 12; 13; 14
A6: 3000217 | B6: BOTA BORBA T38 | C6: 3000217 | D6: 3; 4; 6; 11; 12; 13; 14
A7: 3000218 | B7: BOTA BORBA T39 | C7: 3000218 | D7: 3; 4; 6; 11; 12; 13; 14
A8: 3000219 | B8: BOTA BORBA T40 | C8: 3000219 | D8: 3; 4; 6; 11; 12; 13; 14
A9: 3000220 | B9: BOTA BORBA T41 | C9: 3000220 | D9: 3; 4; 6; 11; 12; 13; 14
A10: 3000221 | B10: BOTA BORBA T42 | C10: 3000221 | D10: 3; 4; 6; 11; 12; 13; 14
A11: 3000222 | B11: BOTA BORBA T43 | C11: 3000222 | D11: 3; 4; 6; 11; 12; 13; 14
A12: 3000223 | B12: BOTA BORBA T44 | C12: 3000223 | D12: 3; 4; 6; 11; 12; 13; 14
A13: 3000224 | B13: BOTA BORBA T45 | C13: 3000224 | D13: 3; 4; 6; 11; 12; 13; 14
A14: 3000225 | B14: BOTA BORBA T46 | C14: 3000225 | D14: 3; 4; 6; 11; 12; 13; 14
A15: 3000226 | B15: BOTA BORBA T47 | C15: 3000226 | D15: 3; 4; 6; 11; 12; 13; 14
A16: 3000236 | B16: BOTA OXFORD T37 | C16: 3000236 | D16: 3; 4; 6; 11; 12; 13; 14
... A39: 3000259 | B39: BOTA PVC BIQ/PALM AÇO SAFETY T48 | C39: 3000259 | D39: 3; 4; 6; 11; 12; 13; 25
A40: 3000359 | B40: CADEIRA SUSPENSA P/ALTURA - BA100 | C40: 3000359 | D40: 1
A41: 3000364 | B41: CALÇA AZUL TAM. 3XL | C41: 3000364 | D41: 5; 11; 13
A42: 3000365 | B42: CALÇA AZUL TAM. L | C42: 3000365 | D42: 5; 11; 14
A43: 3000366 | B43: CALÇA AZUL TAM. M | C43: 3000366 | D43: 5; 11; 15
A44: 3000367 | B44: CALÇA AZUL TAM. S | C44: 3000367 | D44: 5; 11; 16
A45: 3000368 | B45: CALÇA AZUL TAM. XL | C45: 3000368 | D45: 5; 11; 17
A46: 3000369 | B46: CALÇA AZUL TAM. XXL | C46: 3000369 | D46: 5; 11; 18
A47: 3000376 | B47: CALÇA IMPERMIÁVEL C/ REFLETOR TAM. 3XL | C47: 3000376 | D47: 5; 11; 19
A48: 3000377 | B48: CALÇA IMPERMIÁVEL C/ REFLETOR TAM. L | C48: 3000377 | D48: 5; 11; 20
A49: 3000378 | B49: CALÇA IMPERMIÁVEL C/ REFLETOR TAM. M | C49: 3000378 | D49: 5; 11; 21
A50: 3000379 | B50: CALÇA IMPERMIÁVEL C/ REFLETOR TAM. S | C50: 3000379 | D50: 5; 11; 22
A51: 3000380 | B51: CALÇA IMPERMIÁVEL C/ REFLETOR TAM. XL | C51: 3000380 | D51: 5; 11; 23
A52: 3000381 | B52: CALÇA IMPERMIÁVEL C/ REFLETOR TAM. XXL | C52: 3000381 | D52: 5; 11; 24
... A61: 3000395 | B61: CAPACETE VERTEX HELMET BRANCO | C61: 3000395 | D61: 1; 2; 3; 9; 12; 13
A62: 3000405 | B62: CARRINHO CALHA SOL BODY CONTROL I | C62: 3000405 | D62: 1
A63: 3000408 | B63: CHAPÉU DE SOL C/PROTEÇÃO LATERAL | C63: 3000408 | D63: 1
A64: 3000445 | B64: CINTA ANCORAGEM ANNEAU 150CM (VERMELHO) | C64: 3000445 | D64: 5; 6; 13; 14
A65: 3000446 | B65: CINTA ANCORAGEM ANNEAU PMMC40 120CM (VERDE) | C65: 3000446 | D65: 5; 6; 13; 14
A66: 3000447 | B66: CINTA ANCORAGEM ANNEAU PMMC40 60CM (AMARELO) | C66: 3000447 | D66: 5; 6; 13; 14
A67: 3000448 | B67: CINTA C/ CATRACA 1000/3000KG - 8.5MT | C67: 3000448 | D67: 5; 6; 13; 14
A68: 3000449 | B68: CINTA C/ CATRACA 1000KG 5.70MT | C68: 3000449 | D68: 5; 6; 13; 14
A69: 3000450 | B69: CINTA C/ CATRACA 1500KG 6.5MT | C69: 3000450 | D69: 5; 6; 13; 14
A70: 3000451 | B70: CINTA C/ CATRACA 160KG 3MT | C70: 3000451 | D70: 5; 6; 13; 14
...

Sheet Funcionários
A1: Nº | B1: COLABORADORES | C1: Nº
A2: 368 | B2: Adriano Oliveira de Souza | C2: =A2 -> 368
A3: 476 | B3: Ailton Pereira | C3: =A3 -> 476
A4: 382 | B4: Alexandre Vaz | C4: =A4 -> 382
A5: 153 | B5: Alisson André Machado Nogueira | C5: =A5 -> 153
A6: 361 | B6: Alisson Silva de Oliveira | C6: =A6 -> 361
A7: 66 | B7: Alisson Torres Emerick | C7: =A7 -> 66
A8: 232 | B8: Allan Vieira | C8: =A8 -> 232
A9: 234 | B9: Amadeu Neto | C9: =A9 -> 234
A10: 220 | B10: Amos Krebel | C10: =A10 -> 220
A11: 173 | B11: Anderson Ferreira Rodrigues de Oliveira | C11: =A11 -> 173
A12: 344 | B12: Anderson Junior | C12: =A12 -> 344
A13: 114 | B13: Anderson Rufino da Silva | C13: =A13 -> 114
... A319: 646 | B319: Wemerson Oliveira | C319: =A319 -> 646
B320: Valcu Ioan
B321: Cioclei Vasile
B322: Gaspar Dumitru
B323: Garspar Nicolae
B324: Cioaba Aris
B325: Munteanu Florin
B326: Gaspar Ion
B327: Dogaru Ion
B328: Teslici Ionut
B329: Paveloiu Romica
B330: Gaspar Constantin
B331: Dadalau Vasile
